Traceback (most recent call last):
  File "eu4_randomizer.py", line 437, in <module>
  File "tkinter\__init__.pyc", line 2261, in __init__
_tkinter.TclError: Can't find a usable init.tcl in the following directories: 
    {C:\Users\valen\Desktop\git\eu4_randomizer\dist\lib\tcl} C:/Users/valen/Desktop/git/eu4_randomizer/dist/lib/tcl8.6 C:/Users/valen/Desktop/git/eu4_randomizer/lib/tcl8.6 C:/Users/valen/Desktop/git/eu4_randomizer/lib/tcl8.6 C:/Users/valen/Desktop/git/lib/tcl8.6 C:/Users/valen/Desktop/git/eu4_randomizer/library C:/Users/valen/Desktop/git/library C:/Users/valen/Desktop/git/tcl8.6.9/library C:/Users/valen/Desktop/tcl8.6.9/library



This probably means that Tcl wasn't installed properly.


During handling of the above exception, another exception occurred:

Traceback (most recent call last):
  File "eu4_randomizer.py", line 444, in <module>
  File "tkinter\messagebox.pyc", line 94, in showerror
  File "tkinter\messagebox.pyc", line 72, in _show
  File "tkinter\commondialog.pyc", line 40, in show
  File "tkinter\__init__.pyc", line 3119, in __init__
  File "tkinter\__init__.pyc", line 2561, in __init__
  File "tkinter\__init__.pyc", line 2527, in _setup
  File "tkinter\__init__.pyc", line 2261, in __init__
_tkinter.TclError: Can't find a usable init.tcl in the following directories: 
    {C:\Users\valen\Desktop\git\eu4_randomizer\dist\lib\tcl} C:/Users/valen/Desktop/git/eu4_randomizer/dist/lib/tcl8.6 C:/Users/valen/Desktop/git/eu4_randomizer/lib/tcl8.6 C:/Users/valen/Desktop/git/eu4_randomizer/lib/tcl8.6 C:/Users/valen/Desktop/git/lib/tcl8.6 C:/Users/valen/Desktop/git/eu4_randomizer/library C:/Users/valen/Desktop/git/library C:/Users/valen/Desktop/git/tcl8.6.9/library C:/Users/valen/Desktop/tcl8.6.9/library



This probably means that Tcl wasn't installed properly.

Traceback (most recent call last):
  File "eu4_randomizer.py", line 437, in <module>
  File "tkinter\__init__.pyc", line 2261, in __init__
_tkinter.TclError: Can't find a usable init.tcl in the following directories: 
    {C:\Users\valen\Desktop\git\eu4_randomizer\dist\lib\tcl} C:/Users/valen/Desktop/git/eu4_randomizer/dist/lib/tcl8.6 C:/Users/valen/Desktop/git/eu4_randomizer/lib/tcl8.6 C:/Users/valen/Desktop/git/eu4_randomizer/lib/tcl8.6 C:/Users/valen/Desktop/git/lib/tcl8.6 C:/Users/valen/Desktop/git/eu4_randomizer/library C:/Users/valen/Desktop/git/library C:/Users/valen/Desktop/git/tcl8.6.9/library C:/Users/valen/Desktop/tcl8.6.9/library



This probably means that Tcl wasn't installed properly.


During handling of the above exception, another exception occurred:

Traceback (most recent call last):
  File "eu4_randomizer.py", line 444, in <module>
  File "tkinter\messagebox.pyc", line 94, in showerror
  File "tkinter\messagebox.pyc", line 72, in _show
  File "tkinter\commondialog.pyc", line 40, in show
  File "tkinter\__init__.pyc", line 3119, in __init__
  File "tkinter\__init__.pyc", line 2561, in __init__
  File "tkinter\__init__.pyc", line 2527, in _setup
  File "tkinter\__init__.pyc", line 2261, in __init__
_tkinter.TclError: Can't find a usable init.tcl in the following directories: 
    {C:\Users\valen\Desktop\git\eu4_randomizer\dist\lib\tcl} C:/Users/valen/Desktop/git/eu4_randomizer/dist/lib/tcl8.6 C:/Users/valen/Desktop/git/eu4_randomizer/lib/tcl8.6 C:/Users/valen/Desktop/git/eu4_randomizer/lib/tcl8.6 C:/Users/valen/Desktop/git/lib/tcl8.6 C:/Users/valen/Desktop/git/eu4_randomizer/library C:/Users/valen/Desktop/git/library C:/Users/valen/Desktop/git/tcl8.6.9/library C:/Users/valen/Desktop/tcl8.6.9/library



This probably means that Tcl wasn't installed properly.

